Workbook

Sheet Summary
A1: Code Conflicts Audit — Racquets & Strings
A2: Local working tree as of 2026-08-14 (incl. uncommitted changes). Counts below are formulas over the Findings sheet.
A4: Total findings | B4: Count
A5: All | B5: =COUNTA(Findings!$A$2:$A$39)
A7: By severity | B7: Count
A8: High | B8: =COUNTIF(Findings!$D$2:$D$39,A8)
A9: Medium | B9: =COUNTIF(Findings!$D$2:$D$39,A9)
A10: Low | B10: =COUNTIF(Findings!$D$2:$D$39,A10)
A12: By category | B12: High | C12: Medium | D12: Low | E12: Total
A13: Architecture rules | B13: =COUNTIFS(Findings!$B$2:$B$39,$A13,Findings!$D$2:$D$39,"High") | C13: =COUNTIFS(Findings!$B$2:$B$39,$A13,Findings!$D$2:$D$39,"Medium") | D13: =COUNTIFS(Findings!$B$2:$B$39,$A13,Findings!$D$2:$D$39,"Low") | E13: =SUM(B13:D13)
A14: Contacts & privacy | B14: =COUNTIFS(Findings!$B$2:$B$39,$A14,Findings!$D$2:$D$39,"High") | C14: =COUNTIFS(Findings!$B$2:$B$39,$A14,Findings!$D$2:$D$39,"Medium") | D14: =COUNTIFS(Findings!$B$2:$B$39,$A14,Findings!$D$2:$D$39,"Low") | E14: =SUM(B14:D14)
A15: Docs vs code | B15: =COUNTIFS(Findings!$B$2:$B$39,$A15,Findings!$D$2:$D$39,"High") | C15: =COUNTIFS(Findings!$B$2:$B$39,$A15,Findings!$D$2:$D$39,"Medium") | D15: =COUNTIFS(Findings!$B$2:$B$39,$A15,Findings!$D$2:$D$39,"Low") | E15: =SUM(B15:D15)
A16: Draw placement | B16: =COUNTIFS(Findings!$B$2:$B$39,$A16,Findings!$D$2:$D$39,"High") | C16: =COUNTIFS(Findings!$B$2:$B$39,$A16,Findings!$D$2:$D$39,"Medium") | D16: =COUNTIFS(Findings!$B$2:$B$39,$A16,Findings!$D$2:$D$39,"Low") | E16: =SUM(B16:D16)
A17: Hand-synced mirrors | B17: =COUNTIFS(Findings!$B$2:$B$39,$A17,Findings!$D$2:$D$39,"High") | C17: =COUNTIFS(Findings!$B$2:$B$39,$A17,Findings!$D$2:$D$39,"Medium") | D17: =COUNTIFS(Findings!$B$2:$B$39,$A17,Findings!$D$2:$D$39,"Low") | E17: =SUM(B17:D17)
A18: Leaderboards & rank | B18: =COUNTIFS(Findings!$B$2:$B$39,$A18,Findings!$D$2:$D$39,"High") | C18: =COUNTIFS(Findings!$B$2:$B$39,$A18,Findings!$D$2:$D$39,"Medium") | D18: =COUNTIFS(Findings!$B$2:$B$39,$A18,Findings!$D$2:$D$39,"Low") | E18: =SUM(B18:D18)
A19: Points & scoring | B19: =COUNTIFS(Findings!$B$2:$B$39,$A19,Findings!$D$2:$D$39,"High") | C19: =COUNTIFS(Findings!$B$2:$B$39,$A19,Findings!$D$2:$D$39,"Medium") | D19: =COUNTIFS(Findings!$B$2:$B$39,$A19,Findings!$D$2:$D$39,"Low") | E19: =SUM(B19:D19)
A20: Security rules vs code | B20: =COUNTIFS(Findings!$B$2:$B$39,$A20,Findings!$D$2:$D$39,"High") | C20: =COUNTIFS(Findings!$B$2:$B$39,$A20,Findings!$D$2:$D$39,"Medium") | D20: =COUNTIFS(Findings!$B$2:$B$39,$A20,Findings!$D$2:$D$39,"Low") | E20: =SUM(B20:D20)
A21: Skill bands & divisions | B21: =COUNTIFS(Findings!$B$2:$B$39,$A21,Findings!$D$2:$D$39,"High") | C21: =COUNTIFS(Findings!$B$2:$B$39,$A21,Findings!$D$2:$D$39,"Medium") | D21: =COUNTIFS(Findings!$B$2:$B$39,$A21,Findings!$D$2:$D$39,"Low") | E21: =SUM(B21:D21)
A22: Theme rules | B22: =COUNTIFS(Findings!$B$2:$B$39,$A22,Findings!$D$2:$D$39,"High") | C22: =COUNTIFS(Findings!$B$2:$B$39,$A22,Findings!$D$2:$D$39,"Medium") | D22: =COUNTIFS(Findings!$B$2:$B$39,$A22,Findings!$D$2:$D$39,"Low") | E22: =SUM(B22:D22)
A23: Tournament advancement | B23: =COUNTIFS(Findings!$B$2:$B$39,$A23,Findings!$D$2:$D$39,"High") | C23: =COUNTIFS(Findings!$B$2:$B$39,$A23,Findings!$D$2:$D$39,"Medium") | D23: =COUNTIFS(Findings!$B$2:$B$39,$A23,Findings!$D$2:$D$39,"Low") | E23: =SUM(B23:D23)
A24: Zones | B24: =COUNTIFS(Findings!$B$2:$B$39,$A24,Findings!$D$2:$D$39,"High") | C24: =COUNTIFS(Findings!$B$2:$B$39,$A24,Findings!$D$2:$D$39,"Medium") | D24: =COUNTIFS(Findings!$B$2:$B$39,$A24,Findings!$D$2:$D$39,"Low") | E24: =SUM(B24:D24)
A26: By page / workflow (a finding can count in several) | B26: Count
A27: Tournament | B27: =COUNTIF(Findings!$C$2:$C$39,"*"&A27&"*")
A28: Matches | B28: =COUNTIF(Findings!$C$2:$C$39,"*"&A28&"*")
A29: Leagues | B29: =COUNTIF(Findings!$C$2:$C$39,"*"&A29&"*")
A30: Events | B30: =COUNTIF(Findings!$C$2:$C$39,"*"&A30&"*")
A31: Sign up | B31: =COUNTIF(Findings!$C$2:$C$39,"*"&A31&"*")
A32: Profile | B32: =COUNTIF(Findings!$C$2:$C$39,"*"&A32&"*")
A33: Tasks | B33: =COUNTIF(Findings!$C$2:$C$39,"*"&A33&"*")
A34: Services | B34: =COUNTIF(Findings!$C$2:$C$39,"*"&A34&"*")
A35: Marketplace | B35: =COUNTIF(Findings!$C$2:$C$39,"*"&A35&"*")
A36: Courts | B36: =COUNTIF(Findings!$C$2:$C$39,"*"&A36&"*")
A37: Home | B37: =COUNTIF(Findings!$C$2:$C$39,"*"&A37&"*")
A38: Cloud Functions | B38: =COUNTIF(Findings!$C$2:$C$39,"*"&A38&"*")
A39: Docs | B39: =COUNTIF(Findings!$C$2:$C$39,"*"&A39&"*")
A41: By nature | B41: Count
A42: Conflicting logic | B42: =COUNTIF(Findings!$E$2:$E$39,A42)
A43: Doc contradicts code | B43: =COUNTIF(Findings!$E$2:$E$39,A43)
A44: Duplicate logic (drifted) | B44: =COUNTIF(Findings!$E$2:$E$39,A44)
A45: Duplicate logic (in sync) | B45: =COUNTIF(Findings!$E$2:$E$39,A45)
...

Sheet Findings
A1: ID | B1: Category | C1: Page / Workflow | D1: Severity | E1: Nature | F1: Intentional / documented? | G1: Finding | H1: Logic A (what & where) | I1: Logic B / C (what & where) | J1: The contradiction | K1: Impact / risk | L1: Recommendation | M1: Files | N1: Verified how
A2: C-01 | B2: Points & scoring | C2: Tasks / Profile / Leagues | D2: High | E2: Conflicting logic | F2: No | G2: "Matches played" is counted three different ways | H2: stats.matchesPlayed — useTournament.ts:1306-1330 increments on EVERY completed tournament match, walkovers included, and credits doubles partners (statUidsFor); ladderService.ts:187-191 adds non-tournament-sourced challenges; functions/friendlyPoints.js:59-69 adds confirmed friendlies. Shown as the 'Matches' tile on Profile, PlayerProfile, Leagues; drives Matches-page filters and useStandings 'matches organized'. | I2: tasks.matchesPlayed — functions/taskPoints.js:176-194 counts only singles/doubles with a real score, walkover excluded, CAPTAINS only (player_1_uid/player_2_uid), never decremented on reset/delete; friendlies never counted. This is what awards the 'Play 5/10/20/30/50 matches' tiers. Third: useTasks.ts:206-219 recomputes matchesPlayed client-side from matchHistory.ts (walkover-excluded tournament matches) and spreads it OVER the stored value (line 237) — so the Tasks page displays a number the tier engine did not use. | J2: Three inclusion rules for one word. Your Jul-20 rule ('played = real score, no walkover') is applied to tasks but not to stats. | K2: Same member sees different 'matches' counts on Profile vs Tasks; a doubles partner never progresses 'Play N matches'; a draw reset lowers stats and the client-derived bar but leaves the awarded tier; a friendly counts on Profile but not toward the tier. | L2: Decide the definition once (recommend: real score, not walkover/no-show, partners included). Make the server counter authoritative and display it; credit partners in taskPoints; decrement on match delete/reset. Delete the client recompute. | M2: src/pages/tournament/useTournament.ts; src/features/leagues/ladderService.ts; functions/friendlyPoints.js; functions/taskPoints.js; src/features/tasks/matchHistory.ts; src/features/tasks/useTasks.ts; src/features/leagues/useStandings.ts | N2: Read all writers; grep matchesPlayed across src+functions
A3: C-02 | B3: Points & scoring | C3: Matches (Friendlies) / Leagues / Services | D3: High | E3: Doc contradicts code | F3: No | G3: Friendlies now pay league points — CLAUDE.md and the handover say they don't | H3: CLAUDE.md §Leagues, Friendlies & Matches and TECHNICAL_HANDOVER.md §1: friendlies have 'no points, standings impact, or organizer step'. | I3: functions/friendlyPoints.js:25-69 pays winner +2 / loser +1 leaguePoints26 plus matchesPlayed and wins/loses on rally confirm; firestore.rules:305-322 exists specifically to make that payout safe. | J3: Documentation and code state opposite policies for the same feature. | K3: Friendlies move the Leagues table (sorted by leaguePoints26), the weekly rank, win-rate, AND the redeemable balance (functions/rewards.js:64 sums leaguePoints26) — spendable on Services. | L3: Confirm the policy you want. If friendlies should pay, rewrite CLAUDE.md/handover and say so in the FAQ; if not, remove the trigger and reverse paid rows. | M3: functions/friendlyPoints.js; functions/rewards.js; CLAUDE.md; TECHNICAL_HANDOVER.md; firestore.rules | N3: Read friendlyPoints.js; grep leaguePoints26
A4: C-03 | B4: Points & scoring | C4: Tournament / Matches / Leagues | D4: Medium | E4: Multiple logics on one thing | F4: No | G4: leaguePoints26 has five independent writers with five rule sets (CLAUDE.md says one) | H4: useTournament.ts via matchAward (RR 3/1, knockout loser by round R32:1…F:10, winner 20 only at the final, no-show 1 each) + organizer RR +5 bonus (handleSetGroupBonus). | I4: ladderService.confirmChallenge ±3 with loser floored at 0; functions/friendlyPoints.js +2/+1; functions/rankSnapshot.js writes rankPosition/rankTrend beside it; profileService/Signup write skill/league on the same doc. CLAUDE.md §Stats data flow: 'One source writes to stats/{userId} at runtime'. | J4: One aggregate field is fed by tournament, ladder and friendly rules and then displayed per division tab and spent as currency; the doc denies the other writers exist. | K4: Impossible to audit where a member's points came from; policy changes must be found in five files. | L4: Keep one aggregate but add per-source counters (tournament_pts / ladder_pts / friendly_pts) so totals reconcile; replace the CLAUDE.md sentence with a writer table. | M4: src/pages/tournament/utils.ts (matchAward); useTournament.ts; ladderService.ts; functions/friendlyPoints.js; functions/rankSnapshot.js; CLAUDE.md | N4: grep leaguePoints26 (18 files)
A5: C-04 | B5: Points & scoring | C5: Tournament (Doubles) / Tasks | D5: Medium | E5: Conflicting logic | F5: No | G5: Doubles partner credit: stats engine credits partners, task engine credits captains only | H5: useTournament.ts:1284-1330 statUidsFor(): both captains AND their partner_uid receive matchesPlayed/wins/games/points; reverseMatchStatsInto undoes the same set. | I5: functions/taskPoints.js:186-192 awardPairPoints uses player_1_uid/player_2_uid only — partners get no matchesPlayed, streak, months-active or tier progress. | J5: Two engines disagree on who played a doubles match. | K5: A doubles partner's Profile shows matches/wins but their Tasks tiers never move from doubles. | L5: Pass partner uids to awardPairPoints (read event_participants.partner_uid the way the client does). | M5: src/pages/tournament/useTournament.ts; functions/taskPoints.js | N5: Read both credit paths
A6: C-05 | B6: Points & scoring | C6: Tournament | D6: Medium | E6: Latent bug | F6: No | G6: walkover flag is never cleared when a walkover is re-scored with a real result | H6: useTournament.ts:1272 writes `...(isWalkover ? { walkover: true } : {})` — the flag is only ever SET on the normal path. The no-show path (1245) and the reset path (1825) do write walkover:false. | I6: rrGeneration.ts:300-301 computeGroupStandings explicitly handles 'a walkover with a score alongside the flag'; taskPoints.js:184, groupAwards.js:143/167 and matchHistory.ts:19 all EXCLUDE any match with walkover===true; RRGroupCard.tsx:331 prints 'Walkover'. | J6: A match recorded as a walkover then corrected to a real score keeps walkover:true. | K6: That match pays games/points in stats but is excluded from task tiers and Matchday bonuses and is labelled 'Walkover' next to a real score. | L6: Write `walkover: !!isWalkover` on every score write, not only when true. | M6: src/pages/tournament/useTournament.ts:1272; src/pages/tournament/rrGeneration.ts:300 | N6: Read updateMatchWithSubmission write payload
A7: C-06 | B7: Points & scoring | C7: Tournament | D7: Low | E7: Multiple logics on one thing | F7: No | G7: Walkover carried under two names and detected two ways | H7: Match docs: `walkover` (boolean flag, authoritative for every server reader). | I7: Score-submission docs: `is_walkover` (useTournament.ts:1727) — derived from 'all sets 0-0' at submit time (line 1712). Server readers only trust the flag; adminMetricsCompute.js:97-103 must test no_show before walkover because both are all-zero scores. | J7: Same concept, two field names and two detection styles (derived vs flagged). | K7: Low today; any new reader that infers walkover from zeros will misclassify no-shows. | L7: Rename is_walkover → walkover on submissions; treat the flag as the only definition. | M7: src/pages/tournament/useTournament.ts:1712,1727; functions/lib/adminMetricsCompute.js:97-103 | N7: grep walkover
A8: C-07 | B8: Points & scoring | C8: Tournament / Tasks | D8: Medium | E8: Conflicting logic | F8: No | G8: A tournament match converted to a ladder challenge is double-counted by the task engine | H8: ladderService.ts:156-162 confirmChallenge: when `source === 'tournament'` it adds only the ±3 and deliberately does NOT re-count matchesPlayed/wins — 'counting again would double the same match'. | I8: functions/taskPoints.js:197-213 onLadderConfirmedAwardPoints awards source:'ladder' (challengesPlayed, streak, months) for EVERY confirmed challenge — no check of `source` — so the same physical match already counted as a tournament match by onMatchCompletedAwardPoints is counted a second time as a challenge. | J8: Client engine dedupes the conversion; server engine doesn't. | K8: Converted matches inflate challengesPlayed/challengesWon and streaks (tier points are spendable). | L8: In onLadderConfirmedAwardPoints skip (or count differently) when after.source === 'tournament'. | M8: src/features/leagues/ladderService.ts:156-162; functions/taskPoints.js:197-213 | N8: Read both
A9: C-08 | B9: Points & scoring | C9: Tournament (RR) | D9: Low | E9: Multiple logics on one thing | F9: No | G9: RR group card mixes lifetime stats with group-scoped results | H9: RRGroupCard.tsx:262 'MP' column and P/G% come from statsByUid (lifetime stats.matchesPlayed / pointswon — every source incl. ladder & friendlies). | I9: The same table's W/L/points columns come from computeGroupStandings — this group's matches only (rrGeneration.ts:266-320). | J9: One row shows two different scopes without saying so. | K9: Members read 'MP 14' beside 'W 2 L 1' and assume group scope. | L9: Label the lifetime columns ('Career MP') or drop them from the group table. | M9: src/pages/tournament/RRGroupCard.tsx:36,262; src/pages/tournament/rrGeneration.ts:266-320 | N9: Read RRGroupCard props
A10: C-09 | B10: Skill bands & divisions | C10: Profile / Sign up / Matches | D10: Medium | E10: Conflicting logic | F10: No | G10: Four skill-band label sets: 'Beginners' vs 'Beginner', 'Challengers' vs 'Challenger' | H10: utils.ts:287 skillBand() → 'Beginners' | 'Challengers' | 'Masters' (used by draws, Signup, Profile, Matches, OpponentPanels). | I10: skillLevels.ts:19 skillTier() → 'Beginner' | 'Challenger' | 'Masters' (PlayerProfile.tsx:259, ProfileInfo.tsx:511 badge); SKILL_LEVEL_TIERS labels 'Beginner'/'Challengers'/'Masters' (mixed, CompleteProfileModal); TOURNAMENT_OPTIONS names plural. | J10: Same thresholds (<3, <4), four different strings for the same band. | K10: A member's badge reads 'Challenger' on their profile and 'Challengers' everywhere else; any string comparison against the wrong variant silently fails. | L10: Delete skillTier and SKILL_LEVEL_TIERS' own labels; derive every label from one constant next to skillBand. | M10: src/pages/tournament/utils.ts:287; src/utils/skillLevels.ts:7-19; src/pages/PlayerProfile.tsx:259; src/features/profile/components/ProfileInfo.tsx:511 | N10: grep skillTier|skillBand
A11: C-10 | B11: Skill bands & divisions | C11: Events (Join) | D11: Medium | E11: Conflicting logic | F11: No | G11: Join-time slot search uses a fifth skill mapping that has no Beginners band | H11: useJoin.ts:114-115 `intendedGroup = skill >= 4 ? 'Masters' : 'Challengers'` (alt = the other) — a 2.0–2.5 player is searched in Challengers. | I11: drawConfigs.ts:4-11 defines Men's/Women's BEGINNERS draws; utils.ts:450-452 filters participants into draws with skillBand() (<3 → Beginners); rrGeneration buckets by skillBand. | J11: The join gate looks for slots in a band the draw engine will not place the player in. | K11: A beginner can be told the event is 'full' while the Beginners draw has room, or be seated (by an organizer self-join) into a Challengers slot they'd be filtered out of. | L11: Use skillBand() in useJoin and search the Beginners draw first for <3. | M11: src/features/events/hooks/useJoin.ts:107-116; src/pages/tournament/drawConfigs.ts:4-11; src/pages/tournament/utils.ts:450-452 | N11: Read useJoin.slotStatus
A12: C-11 | B12: Skill bands & divisions | C12: Leagues / Cloud Functions | D12: Medium | E12: Duplicate logic (drifted) | F12: No | G12: Division-from-league parsed three ways, with overlapping buckets | H12: skillLevels.ts:23 leagueDivision(): Women's if 'wom'/'female', Men's if 'men'/'male', else '' — no Doubles at all. | I12: useStandings.ts:35-41 inDivision(): mens = ('men'|'male') AND NOT women; womens = 'wom'|'female'; doubles = 'double'|'mixed'. Mirrored verbatim in functions/rankSnapshot.js:19-27 ('keep in sync'). | J12: 'Women's Doubles' satisfies womens AND doubles; 'Men's Doubles' satisfies mens AND doubles; leagueDivision returns '' for any doubles league. | K12: rankSnapshot ranks such a player in two tabs and writes ONE rankPosition (last tab wins); Profile league selector shows blank for doubles leagues. | L12: One exported parser used by client and (via mirror test) server; make the buckets mutually exclusive. | M12: src/utils/skillLevels.ts:23-28; src/features/leagues/useStandings.ts:35-41; functions/rankSnapshot.js:19-27 | N12: Read all three
... A39: C-38 | B39: Hand-synced mirrors | C39: Tournament / Cloud Functions | D39: Low | E39: Multiple logics on one thing | F39: Yes | G39: PLAYER_LOADING vs PLAYER_LOADING_SENTINEL, plus string literals in functions | H39: utils.ts:81 PLAYER_LOADING = 'Player Loading' (the name stored on match docs; mirrored as a literal in functions/zoneMoves.js:33 and referenced in connections.js:96). | I39: AddPlayerPanel.tsx:7 PLAYER_LOADING_SENTINEL = '__player_loading__' (dropdown value; RRGroupCard.tsx:380, useTournament.ts:1875). | J39: Two constants for 'the placeholder player', one of them re-typed by hand server-side. | K39: A rename of the display string breaks zone moves and connections silently. | L39: Export the display constant to a shared JSON both packages import, or add it to the parity script (C-24). | M39: src/pages/tournament/utils.ts:81; src/pages/tournament/AddPlayerPanel.tsx:7; functions/zoneMoves.js:33 | N39: grep PLAYER_LOADING

Sheet Legend
A1: Column | B1: Meaning
A2: ID | B2: Stable reference (C-01…). Use it in commits/PRs that resolve the finding.
A3: Category | B3: What kind of thing conflicts: Points & scoring · Skill bands & divisions · Leaderboards & rank · Tournament advancement · Draw placement · Zones · Contacts & privacy · Security rules vs code · Architecture rules · Theme rules · Docs vs code · Hand-synced mirrors.
A4: Page / Workflow | B4: Where a user (or operator) meets it. Several pages may be listed; the Summary counts a finding under each page it names.
A5: Severity | B5: High = wrong points/visibility/data for members today. Medium = user-visible inconsistency or a latent bug with a clear trigger. Low = drift risk, vestigial code, cosmetic or documentation.
A6: Nature | B6: Conflicting logic (two implementations disagree) · Multiple logics on one thing (same concept computed in >1 place) · Duplicate logic (in sync) (same rule written twice, identical today — needs a parity test) · Duplicate logic (drifted) (written twice and already different) · Doc contradicts code · Rules vs code · Field with two meanings · Vestigial / dead config · Rule violation (breaks a codified CLAUDE.md rule) · Latent bug.
A7: Intentional / documented? | B7: Yes = a by-design or documented duplication (mirrors across the language boundary, deliberate two-path features, deploy-order fallbacks). Filter to No for the rows that need a decision or a fix.
A8: Logic A / Logic B | B8: The competing implementations, each with file:line from the local tree on 2026-08-14.
A9: Verified how | B9: What was read or grepped to confirm the row. Nothing here is inferred from documentation alone unless the row says so.
A11: Method | B11: Reviewed src/, functions/, firestore.rules and the root documents; verified every documented duplication in CLAUDE.md / Tournament_Logic_Report against current code and hunted for undocumented ones (skill mappings, 'played' definitions, walkover handling, slot predicates, division parsers, leaderboard sorts, public counters, roster loaders, theme tokens, docs vs deleted files).
A12: Not covered | B12: The DEPLOYED Firestore rules were not diffed against the repo copy (CLAUDE.md warns they can differ). Notification type coverage, storage.rules, and the Admin scripts in scripts/ (other than snapshot-ranks.mjs) were not audited. Intentional, documented duplications are included and marked so you can filter them out.
A13: How to use | B13: Filter Severity = High first (3 rows). Then filter Nature = 'Doc contradicts code' before the handover goes out. Rows marked 'Hand-synced mirror' are not bugs today — they are the list for a parity test.
